{"uid":"2677f4006a158f7b","name":"test_user_registration","fullName":"tests.test_users.TestUsers#test_user_registration","historyId":"8bb43b26ad1d96a78a3961b3077bee32","time":{"start":1689189992738,"stop":1689189995744,"duration":3006},"status":"broken","statusMessage":"requests.exceptions.ConnectionError: HTTPConnectionPool(host='localhost', port=80): Max retries exceeded with url: /api/users/ (Caused by NewConnectionError('<urllib3.connection.HTTPConnection object at 0x7f299b3f0d90>: Failed to establish a new connection: [Errno 111] Connection refused'))","statusTrace":"E   ConnectionRefusedError: [Errno 111] Connection refused\n\nThe above exception was the direct cause of the following exception:\nE   urllib3.exceptions.NewConnectionError: <urllib3.connection.HTTPConnection object at 0x7f299b3f0d90>: Failed to establish a new connection: [Errno 111] Connection refused\n\nThe above exception was the direct cause of the following exception:\nE   urllib3.exceptions.MaxRetryError: HTTPConnectionPool(host='localhost', port=80): Max retries exceeded with url: /api/users/ (Caused by NewConnectionError('<urllib3.connection.HTTPConnection object at 0x7f299b3f0d90>: Failed to establish a new connection: [Errno 111] Connection refused'))\n\nDuring handling of the above exception, another exception occurred:\nE   requests.exceptions.ConnectionError: HTTPConnectionPool(host='localhost', port=80): Max retries exceeded with url: /api/users/ (Caused by NewConnectionError('<urllib3.connection.HTTPConnection object at 0x7f299b3f0d90>: Failed to establish a new connection: [Errno 111] Connection refused'))","flaky":false,"newFailed":false,"newBroken":false,"newPassed":false,"retriesCount":0,"retriesStatusChange":false,"beforeStages":[],"testStage":{"status":"broken","statusMessage":"requests.exceptions.ConnectionError: HTTPConnectionPool(host='localhost', port=80): Max retries exceeded with url: /api/users/ (Caused by NewConnectionError('<urllib3.connection.HTTPConnection object at 0x7f299b3f0d90>: Failed to establish a new connection: [Errno 111] Connection refused'))","statusTrace":"E   ConnectionRefusedError: [Errno 111] Connection refused\n\nThe above exception was the direct cause of the following exception:\nE   urllib3.exceptions.NewConnectionError: <urllib3.connection.HTTPConnection object at 0x7f299b3f0d90>: Failed to establish a new connection: [Errno 111] Connection refused\n\nThe above exception was the direct cause of the following exception:\nE   urllib3.exceptions.MaxRetryError: HTTPConnectionPool(host='localhost', port=80): Max retries exceeded with url: /api/users/ (Caused by NewConnectionError('<urllib3.connection.HTTPConnection object at 0x7f299b3f0d90>: Failed to establish a new connection: [Errno 111] Connection refused'))\n\nDuring handling of the above exception, another exception occurred:\nE   requests.exceptions.ConnectionError: HTTPConnectionPool(host='localhost', port=80): Max retries exceeded with url: /api/users/ (Caused by NewConnectionError('<urllib3.connection.HTTPConnection object at 0x7f299b3f0d90>: Failed to establish a new connection: [Errno 111] Connection refused'))","steps":[],"attachments":[{"uid":"b19eb60f8730bf04","name":"log","source":"b19eb60f8730bf04.txt","type":"text/plain","size":974}],"parameters":[],"stepsCount":0,"attachmentsCount":1,"shouldDisplayMessage":true,"hasContent":true},"afterStages":[],"labels":[{"name":"feature","value":"Тесты работы с пользователем."},{"name":"story","value":"Тест регистрации пользователя."},{"name":"tag","value":"test_user_registration"},{"name":"tag","value":"users_tests(scope='class')"},{"name":"tag","value":"order(1)"},{"name":"parentSuite","value":"tests"},{"name":"suite","value":"test_users"},{"name":"subSuite","value":"TestUsers"},{"name":"host","value":"fv-az262-296"},{"name":"thread","value":"2338-MainThread"},{"name":"framework","value":"pytest"},{"name":"language","value":"cpython3"},{"name":"package","value":"tests.test_users"},{"name":"resultFormat","value":"allure2"}],"parameters":[],"links":[],"hidden":false,"retry":false,"extra":{"severity":"normal","retries":[],"categories":[{"name":"Test defects","matchedStatuses":[],"flaky":false}],"history":{"statistic":{"failed":0,"broken":2,"skipped":0,"passed":0,"unknown":0,"total":2},"items":[{"uid":"20362f5682bae84a","reportUrl":"https://IlyaYaP.github.io/testing_api_foodgram/26//#testresult/20362f5682bae84a","status":"broken","statusDetails":"requests.exceptions.ConnectionError: HTTPConnectionPool(host='localhost', port=80): Max retries exceeded with url: /api/users/ (Caused by NewConnectionError('<urllib3.connection.HTTPConnection object at 0x7fb31f9fe1d0>: Failed to establish a new connection: [Errno 111] Connection refused'))","time":{"start":1689189537960,"stop":1689189537962,"duration":2}}]},"tags":["order(1)","users_tests(scope='class')","test_user_registration"]},"source":"2677f4006a158f7b.json","parameterValues":[]}