{"uid":"3204436a62871cbf","name":"test_get_ingredient","fullName":"tests.test_ingredients.TestIngredients#test_get_ingredient","historyId":"adf9e8f1ccaef70993531bf3a2a95b28","time":{"start":1689190008104,"stop":1689190008106,"duration":2},"status":"broken","statusMessage":"requests.exceptions.ConnectionError: HTTPConnectionPool(host='localhost', port=80): Max retries exceeded with url: /api/ingredients/123/ (Caused by NewConnectionError('<urllib3.connection.HTTPConnection object at 0x7f299b2af550>: Failed to establish a new connection: [Errno 111] Connection refused'))","statusTrace":"E   ConnectionRefusedError: [Errno 111] Connection refused\n\nThe above exception was the direct cause of the following exception:\nE   urllib3.exceptions.NewConnectionError: <urllib3.connection.HTTPConnection object at 0x7f299b2af550>: Failed to establish a new connection: [Errno 111] Connection refused\n\nThe above exception was the direct cause of the following exception:\nE   urllib3.exceptions.MaxRetryError: HTTPConnectionPool(host='localhost', port=80): Max retries exceeded with url: /api/ingredients/123/ (Caused by NewConnectionError('<urllib3.connection.HTTPConnection object at 0x7f299b2af550>: Failed to establish a new connection: [Errno 111] Connection refused'))\n\nDuring handling of the above exception, another exception occurred:\nE   requests.exceptions.ConnectionError: HTTPConnectionPool(host='localhost', port=80): Max retries exceeded with url: /api/ingredients/123/ (Caused by NewConnectionError('<urllib3.connection.HTTPConnection object at 0x7f299b2af550>: Failed to establish a new connection: [Errno 111] Connection refused'))","flaky":false,"newFailed":false,"newBroken":false,"newPassed":false,"retriesCount":0,"retriesStatusChange":false,"beforeStages":[],"afterStages":[],"labels":[{"name":"story","value":"Тест получения определенного ингредиента."},{"name":"feature","value":"Тесты получения списка рецептов."},{"name":"tag","value":"test_get_ingredient"},{"name":"tag","value":"ingredients_tests(scope='class')"},{"name":"tag","value":"order(6)"},{"name":"parentSuite","value":"tests"},{"name":"suite","value":"test_ingredients"},{"name":"subSuite","value":"TestIngredients"},{"name":"host","value":"fv-az262-296"},{"name":"thread","value":"2338-MainThread"},{"name":"framework","value":"pytest"},{"name":"language","value":"cpython3"},{"name":"package","value":"tests.test_ingredients"},{"name":"resultFormat","value":"allure2"}],"parameters":[],"links":[],"hidden":false,"retry":false,"extra":{"severity":"normal","retries":[],"categories":[{"name":"Test defects","matchedStatuses":[],"flaky":false}],"history":{"statistic":{"failed":0,"broken":2,"skipped":0,"passed":0,"unknown":0,"total":2},"items":[{"uid":"a87ca8f3fa122b5b","reportUrl":"https://IlyaYaP.github.io/testing_api_foodgram/26//#testresult/a87ca8f3fa122b5b","status":"broken","statusDetails":"requests.exceptions.ConnectionError: HTTPConnectionPool(host='localhost', port=80): Max retries exceeded with url: /api/ingredients/123/ (Caused by NewConnectionError('<urllib3.connection.HTTPConnection object at 0x7fb31f8cc7d0>: Failed to establish a new connection: [Errno 111] Connection refused'))","time":{"start":1689189538225,"stop":1689189538226,"duration":1}}]},"tags":["ingredients_tests(scope='class')","test_get_ingredient","order(6)"]},"source":"3204436a62871cbf.json","parameterValues":[]}