{"uid":"380668e4d36a2a19","name":"test_negative_get_current_user","fullName":"tests.test_users.TestUsers#test_negative_get_current_user","historyId":"bdecc3c5cafe3f9ebebb59a04f24e6b8","time":{"start":1689190004818,"stop":1689190007823,"duration":3005},"status":"broken","statusMessage":"requests.exceptions.ConnectionError: HTTPConnectionPool(host='localhost', port=80): Max retries exceeded with url: /api/users/me/ (Caused by NewConnectionError('<urllib3.connection.HTTPConnection object at 0x7f299b42c650>: Failed to establish a new connection: [Errno 111] Connection refused'))","statusTrace":"E   ConnectionRefusedError: [Errno 111] Connection refused\n\nThe above exception was the direct cause of the following exception:\nE   urllib3.exceptions.NewConnectionError: <urllib3.connection.HTTPConnection object at 0x7f299b42c650>: Failed to establish a new connection: [Errno 111] Connection refused\n\nThe above exception was the direct cause of the following exception:\nE   urllib3.exceptions.MaxRetryError: HTTPConnectionPool(host='localhost', port=80): Max retries exceeded with url: /api/users/me/ (Caused by NewConnectionError('<urllib3.connection.HTTPConnection object at 0x7f299b42c650>: Failed to establish a new connection: [Errno 111] Connection refused'))\n\nDuring handling of the above exception, another exception occurred:\nE   requests.exceptions.ConnectionError: HTTPConnectionPool(host='localhost', port=80): Max retries exceeded with url: /api/users/me/ (Caused by NewConnectionError('<urllib3.connection.HTTPConnection object at 0x7f299b42c650>: Failed to establish a new connection: [Errno 111] Connection refused'))","flaky":false,"newFailed":false,"newBroken":false,"newPassed":false,"retriesCount":0,"retriesStatusChange":false,"beforeStages":[],"testStage":{"status":"broken","statusMessage":"requests.exceptions.ConnectionError: HTTPConnectionPool(host='localhost', port=80): Max retries exceeded with url: /api/users/me/ (Caused by NewConnectionError('<urllib3.connection.HTTPConnection object at 0x7f299b42c650>: Failed to establish a new connection: [Errno 111] Connection refused'))","statusTrace":"E   ConnectionRefusedError: [Errno 111] Connection refused\n\nThe above exception was the direct cause of the following exception:\nE   urllib3.exceptions.NewConnectionError: <urllib3.connection.HTTPConnection object at 0x7f299b42c650>: Failed to establish a new connection: [Errno 111] Connection refused\n\nThe above exception was the direct cause of the following exception:\nE   urllib3.exceptions.MaxRetryError: HTTPConnectionPool(host='localhost', port=80): Max retries exceeded with url: /api/users/me/ (Caused by NewConnectionError('<urllib3.connection.HTTPConnection object at 0x7f299b42c650>: Failed to establish a new connection: [Errno 111] Connection refused'))\n\nDuring handling of the above exception, another exception occurred:\nE   requests.exceptions.ConnectionError: HTTPConnectionPool(host='localhost', port=80): Max retries exceeded with url: /api/users/me/ (Caused by NewConnectionError('<urllib3.connection.HTTPConnection object at 0x7f299b42c650>: Failed to establish a new connection: [Errno 111] Connection refused'))","steps":[],"attachments":[{"uid":"1d55de7428ab6187","name":"log","source":"1d55de7428ab6187.txt","type":"text/plain","size":983}],"parameters":[],"stepsCount":0,"attachmentsCount":1,"shouldDisplayMessage":true,"hasContent":true},"afterStages":[],"labels":[{"name":"feature","value":"Тесты работы с пользователем."},{"name":"story","value":"Тест получения информации о текущем пользователе, без авторизации."},{"name":"tag","value":"test_negative_get_current_user_not_logged"},{"name":"tag","value":"users_tests(scope='class')"},{"name":"tag","value":"order(1)"},{"name":"parentSuite","value":"tests"},{"name":"suite","value":"test_users"},{"name":"subSuite","value":"TestUsers"},{"name":"host","value":"fv-az262-296"},{"name":"thread","value":"2338-MainThread"},{"name":"framework","value":"pytest"},{"name":"language","value":"cpython3"},{"name":"package","value":"tests.test_users"},{"name":"resultFormat","value":"allure2"}],"parameters":[],"links":[],"hidden":false,"retry":false,"extra":{"severity":"normal","retries":[],"categories":[{"name":"Test defects","matchedStatuses":[],"flaky":false}],"history":{"statistic":{"failed":0,"broken":2,"skipped":0,"passed":0,"unknown":0,"total":2},"items":[{"uid":"8b574a418a1d8c07","reportUrl":"https://IlyaYaP.github.io/testing_api_foodgram/26//#testresult/8b574a418a1d8c07","status":"broken","statusDetails":"requests.exceptions.ConnectionError: HTTPConnectionPool(host='localhost', port=80): Max retries exceeded with url: /api/users/me/ (Caused by NewConnectionError('<urllib3.connection.HTTPConnection object at 0x7fb31fa25a50>: Failed to establish a new connection: [Errno 111] Connection refused'))","time":{"start":1689189538003,"stop":1689189538004,"duration":1}}]},"tags":["order(1)","test_negative_get_current_user_not_logged","users_tests(scope='class')"]},"source":"380668e4d36a2a19.json","parameterValues":[]}