{"uid":"519fb4f5661d08f5","name":"test_negative_changing_password_user_not_logged","fullName":"tests.test_users.TestUsers#test_negative_changing_password_user_not_logged","historyId":"2c484cb66dc66302baa17f225812f595","time":{"start":1689190007843,"stop":1689190007844,"duration":1},"status":"broken","statusMessage":"requests.exceptions.ConnectionError: HTTPConnectionPool(host='localhost', port=80): Max retries exceeded with url: /api/users/set_password/ (Caused by NewConnectionError('<urllib3.connection.HTTPConnection object at 0x7f299b43b6d0>: Failed to establish a new connection: [Errno 111] Connection refused'))","statusTrace":"E   ConnectionRefusedError: [Errno 111] Connection refused\n\nThe above exception was the direct cause of the following exception:\nE   urllib3.exceptions.NewConnectionError: <urllib3.connection.HTTPConnection object at 0x7f299b43b6d0>: Failed to establish a new connection: [Errno 111] Connection refused\n\nThe above exception was the direct cause of the following exception:\nE   urllib3.exceptions.MaxRetryError: HTTPConnectionPool(host='localhost', port=80): Max retries exceeded with url: /api/users/set_password/ (Caused by NewConnectionError('<urllib3.connection.HTTPConnection object at 0x7f299b43b6d0>: Failed to establish a new connection: [Errno 111] Connection refused'))\n\nDuring handling of the above exception, another exception occurred:\nE   requests.exceptions.ConnectionError: HTTPConnectionPool(host='localhost', port=80): Max retries exceeded with url: /api/users/set_password/ (Caused by NewConnectionError('<urllib3.connection.HTTPConnection object at 0x7f299b43b6d0>: Failed to establish a new connection: [Errno 111] Connection refused'))","flaky":false,"newFailed":false,"newBroken":false,"newPassed":false,"retriesCount":0,"retriesStatusChange":false,"beforeStages":[],"afterStages":[],"labels":[{"name":"feature","value":"Тесты работы с пользователем."},{"name":"story","value":"Тест изменения пароля, без авторизации."},{"name":"tag","value":"test_changing_password_user_not_logged"},{"name":"tag","value":"users_tests(scope='class')"},{"name":"tag","value":"order(1)"},{"name":"parentSuite","value":"tests"},{"name":"suite","value":"test_users"},{"name":"subSuite","value":"TestUsers"},{"name":"host","value":"fv-az262-296"},{"name":"thread","value":"2338-MainThread"},{"name":"framework","value":"pytest"},{"name":"language","value":"cpython3"},{"name":"package","value":"tests.test_users"},{"name":"resultFormat","value":"allure2"}],"parameters":[],"links":[],"hidden":false,"retry":false,"extra":{"severity":"normal","retries":[],"categories":[{"name":"Test defects","matchedStatuses":[],"flaky":false}],"history":{"statistic":{"failed":0,"broken":2,"skipped":0,"passed":0,"unknown":0,"total":2},"items":[{"uid":"54f35b3f7ac90f40","reportUrl":"https://IlyaYaP.github.io/testing_api_foodgram/26//#testresult/54f35b3f7ac90f40","status":"broken","statusDetails":"requests.exceptions.ConnectionError: HTTPConnectionPool(host='localhost', port=80): Max retries exceeded with url: /api/users/set_password/ (Caused by NewConnectionError('<urllib3.connection.HTTPConnection object at 0x7fb31fa3b790>: Failed to establish a new connection: [Errno 111] Connection refused'))","time":{"start":1689189538017,"stop":1689189538018,"duration":1}}]},"tags":["order(1)","users_tests(scope='class')","test_changing_password_user_not_logged"]},"source":"519fb4f5661d08f5.json","parameterValues":[]}