{"uid":"962f7381a73197ec","name":"test_get_subscriptions_user_not_logged","fullName":"tests.test_subscription.TestSubscriptions#test_get_subscriptions_user_not_logged","historyId":"19ffdcefa3b9df970185d80f63b32d70","time":{"start":1689190008020,"stop":1689190008025,"duration":5},"status":"broken","statusMessage":"requests.exceptions.ConnectionError: HTTPConnectionPool(host='localhost', port=80): Max retries exceeded with url: /api/users/subscriptions/ (Caused by NewConnectionError('<urllib3.connection.HTTPConnection object at 0x7f299b287f90>: Failed to establish a new connection: [Errno 111] Connection refused'))","statusTrace":"E   ConnectionRefusedError: [Errno 111] Connection refused\n\nThe above exception was the direct cause of the following exception:\nE   urllib3.exceptions.NewConnectionError: <urllib3.connection.HTTPConnection object at 0x7f299b287f90>: Failed to establish a new connection: [Errno 111] Connection refused\n\nThe above exception was the direct cause of the following exception:\nE   urllib3.exceptions.MaxRetryError: HTTPConnectionPool(host='localhost', port=80): Max retries exceeded with url: /api/users/subscriptions/ (Caused by NewConnectionError('<urllib3.connection.HTTPConnection object at 0x7f299b287f90>: Failed to establish a new connection: [Errno 111] Connection refused'))\n\nDuring handling of the above exception, another exception occurred:\nE   requests.exceptions.ConnectionError: HTTPConnectionPool(host='localhost', port=80): Max retries exceeded with url: /api/users/subscriptions/ (Caused by NewConnectionError('<urllib3.connection.HTTPConnection object at 0x7f299b287f90>: Failed to establish a new connection: [Errno 111] Connection refused'))","flaky":false,"newFailed":false,"newBroken":false,"newPassed":false,"retriesCount":0,"retriesStatusChange":false,"beforeStages":[],"afterStages":[],"labels":[{"name":"story","value":"Тест получения подписок пользователя без авторизации."},{"name":"feature","value":"Тесты осуществления подписки на пользователя."},{"name":"tag","value":"test_get_subscriptions_user_not_logged"},{"name":"tag","value":"subscriptions_tests(scope='class')"},{"name":"tag","value":"order(4)"},{"name":"parentSuite","value":"tests"},{"name":"suite","value":"test_subscription"},{"name":"subSuite","value":"TestSubscriptions"},{"name":"host","value":"fv-az262-296"},{"name":"thread","value":"2338-MainThread"},{"name":"framework","value":"pytest"},{"name":"language","value":"cpython3"},{"name":"package","value":"tests.test_subscription"},{"name":"resultFormat","value":"allure2"}],"parameters":[],"links":[],"hidden":false,"retry":false,"extra":{"severity":"normal","retries":[],"categories":[{"name":"Test defects","matchedStatuses":[],"flaky":false}],"history":{"statistic":{"failed":0,"broken":2,"skipped":0,"passed":0,"unknown":0,"total":2},"items":[{"uid":"ca356e4f34485e55","reportUrl":"https://IlyaYaP.github.io/testing_api_foodgram/26//#testresult/ca356e4f34485e55","status":"broken","statusDetails":"requests.exceptions.ConnectionError: HTTPConnectionPool(host='localhost', port=80): Max retries exceeded with url: /api/users/subscriptions/ (Caused by NewConnectionError('<urllib3.connection.HTTPConnection object at 0x7fb31fa81f10>: Failed to establish a new connection: [Errno 111] Connection refused'))","time":{"start":1689189538164,"stop":1689189538165,"duration":1}}]},"tags":["subscriptions_tests(scope='class')","test_get_subscriptions_user_not_logged","order(4)"]},"source":"962f7381a73197ec.json","parameterValues":[]}