{"uid":"adad3f92e2523852","name":"test_negative_add_recipe_favorites_user_not_logged","fullName":"tests.test_favourites.TestRecipeFavorites#test_negative_add_recipe_favorites_user_not_logged","historyId":"6216d5120ac0239aab4d58de3351c7c5","time":{"start":1689190007971,"stop":1689190007972,"duration":1},"status":"broken","statusMessage":"requests.exceptions.ConnectionError: HTTPConnectionPool(host='localhost', port=80): Max retries exceeded with url: /api/recipes/ (Caused by NewConnectionError('<urllib3.connection.HTTPConnection object at 0x7f299b45bfd0>: Failed to establish a new connection: [Errno 111] Connection refused'))","statusTrace":"E   ConnectionRefusedError: [Errno 111] Connection refused\n\nThe above exception was the direct cause of the following exception:\nE   urllib3.exceptions.NewConnectionError: <urllib3.connection.HTTPConnection object at 0x7f299b45bfd0>: Failed to establish a new connection: [Errno 111] Connection refused\n\nThe above exception was the direct cause of the following exception:\nE   urllib3.exceptions.MaxRetryError: HTTPConnectionPool(host='localhost', port=80): Max retries exceeded with url: /api/recipes/ (Caused by NewConnectionError('<urllib3.connection.HTTPConnection object at 0x7f299b45bfd0>: Failed to establish a new connection: [Errno 111] Connection refused'))\n\nDuring handling of the above exception, another exception occurred:\nE   requests.exceptions.ConnectionError: HTTPConnectionPool(host='localhost', port=80): Max retries exceeded with url: /api/recipes/ (Caused by NewConnectionError('<urllib3.connection.HTTPConnection object at 0x7f299b45bfd0>: Failed to establish a new connection: [Errno 111] Connection refused'))","flaky":false,"newFailed":false,"newBroken":false,"newPassed":false,"retriesCount":0,"retriesStatusChange":false,"beforeStages":[],"afterStages":[],"labels":[{"name":"feature","value":"Тест добавления рецептов в избранное."},{"name":"story","value":"Тест добавления рецептов в избранное, без авторизации"},{"name":"tag","value":"test_negative_add_recipe_favorites_user_not_logged"},{"name":"tag","value":"recipe_favorites_tests(scope='class')"},{"name":"tag","value":"order(3)"},{"name":"parentSuite","value":"tests"},{"name":"suite","value":"test_favourites"},{"name":"subSuite","value":"TestRecipeFavorites"},{"name":"host","value":"fv-az262-296"},{"name":"thread","value":"2338-MainThread"},{"name":"framework","value":"pytest"},{"name":"language","value":"cpython3"},{"name":"package","value":"tests.test_favourites"},{"name":"resultFormat","value":"allure2"}],"parameters":[],"links":[],"hidden":false,"retry":false,"extra":{"severity":"normal","retries":[],"categories":[{"name":"Test defects","matchedStatuses":[],"flaky":false}],"history":{"statistic":{"failed":0,"broken":2,"skipped":0,"passed":0,"unknown":0,"total":2},"items":[{"uid":"322822a2a9c2a78f","reportUrl":"https://IlyaYaP.github.io/testing_api_foodgram/26//#testresult/322822a2a9c2a78f","status":"broken","statusDetails":"requests.exceptions.ConnectionError: HTTPConnectionPool(host='localhost', port=80): Max retries exceeded with url: /api/recipes/ (Caused by NewConnectionError('<urllib3.connection.HTTPConnection object at 0x7fb31fa6f010>: Failed to establish a new connection: [Errno 111] Connection refused'))","time":{"start":1689189538123,"stop":1689189538124,"duration":1}}]},"tags":["order(3)","test_negative_add_recipe_favorites_user_not_logged","recipe_favorites_tests(scope='class')"]},"source":"adad3f92e2523852.json","parameterValues":[]}