{"uid":"efdeb0c66cb8c676","name":"test_negative_user_registration","fullName":"tests.test_users.TestUsers#test_negative_user_registration","historyId":"0c41c7377d01db82d03d4698b1ca5133","time":{"start":1689189995753,"stop":1689189998758,"duration":3005},"status":"broken","statusMessage":"requests.exceptions.ConnectionError: HTTPConnectionPool(host='localhost', port=80): Max retries exceeded with url: /api/users/ (Caused by NewConnectionError('<urllib3.connection.HTTPConnection object at 0x7f299b3f2d50>: Failed to establish a new connection: [Errno 111] Connection refused'))","statusTrace":"E   ConnectionRefusedError: [Errno 111] Connection refused\n\nThe above exception was the direct cause of the following exception:\nE   urllib3.exceptions.NewConnectionError: <urllib3.connection.HTTPConnection object at 0x7f299b3f2d50>: Failed to establish a new connection: [Errno 111] Connection refused\n\nThe above exception was the direct cause of the following exception:\nE   urllib3.exceptions.MaxRetryError: HTTPConnectionPool(host='localhost', port=80): Max retries exceeded with url: /api/users/ (Caused by NewConnectionError('<urllib3.connection.HTTPConnection object at 0x7f299b3f2d50>: Failed to establish a new connection: [Errno 111] Connection refused'))\n\nDuring handling of the above exception, another exception occurred:\nE   requests.exceptions.ConnectionError: HTTPConnectionPool(host='localhost', port=80): Max retries exceeded with url: /api/users/ (Caused by NewConnectionError('<urllib3.connection.HTTPConnection object at 0x7f299b3f2d50>: Failed to establish a new connection: [Errno 111] Connection refused'))","flaky":false,"newFailed":false,"newBroken":false,"newPassed":false,"retriesCount":0,"retriesStatusChange":false,"beforeStages":[],"testStage":{"status":"broken","statusMessage":"requests.exceptions.ConnectionError: HTTPConnectionPool(host='localhost', port=80): Max retries exceeded with url: /api/users/ (Caused by NewConnectionError('<urllib3.connection.HTTPConnection object at 0x7f299b3f2d50>: Failed to establish a new connection: [Errno 111] Connection refused'))","statusTrace":"E   ConnectionRefusedError: [Errno 111] Connection refused\n\nThe above exception was the direct cause of the following exception:\nE   urllib3.exceptions.NewConnectionError: <urllib3.connection.HTTPConnection object at 0x7f299b3f2d50>: Failed to establish a new connection: [Errno 111] Connection refused\n\nThe above exception was the direct cause of the following exception:\nE   urllib3.exceptions.MaxRetryError: HTTPConnectionPool(host='localhost', port=80): Max retries exceeded with url: /api/users/ (Caused by NewConnectionError('<urllib3.connection.HTTPConnection object at 0x7f299b3f2d50>: Failed to establish a new connection: [Errno 111] Connection refused'))\n\nDuring handling of the above exception, another exception occurred:\nE   requests.exceptions.ConnectionError: HTTPConnectionPool(host='localhost', port=80): Max retries exceeded with url: /api/users/ (Caused by NewConnectionError('<urllib3.connection.HTTPConnection object at 0x7f299b3f2d50>: Failed to establish a new connection: [Errno 111] Connection refused'))","steps":[],"attachments":[{"uid":"b9fbd63b39c4719d","name":"log","source":"b9fbd63b39c4719d.txt","type":"text/plain","size":974}],"parameters":[],"stepsCount":0,"attachmentsCount":1,"shouldDisplayMessage":true,"hasContent":true},"afterStages":[],"labels":[{"name":"feature","value":"Тесты работы с пользователем."},{"name":"story","value":"Негативный тест регистрации пользователя:                    указываем невалидные данные."},{"name":"tag","value":"test_negative_user_registration"},{"name":"tag","value":"users_tests(scope='class')"},{"name":"tag","value":"order(1)"},{"name":"parentSuite","value":"tests"},{"name":"suite","value":"test_users"},{"name":"subSuite","value":"TestUsers"},{"name":"host","value":"fv-az262-296"},{"name":"thread","value":"2338-MainThread"},{"name":"framework","value":"pytest"},{"name":"language","value":"cpython3"},{"name":"package","value":"tests.test_users"},{"name":"resultFormat","value":"allure2"}],"parameters":[],"links":[],"hidden":false,"retry":false,"extra":{"severity":"normal","retries":[],"categories":[{"name":"Test defects","matchedStatuses":[],"flaky":false}],"history":{"statistic":{"failed":0,"broken":2,"skipped":0,"passed":0,"unknown":0,"total":2},"items":[{"uid":"36e4478cc4be7cee","reportUrl":"https://IlyaYaP.github.io/testing_api_foodgram/26//#testresult/36e4478cc4be7cee","status":"broken","statusDetails":"requests.exceptions.ConnectionError: HTTPConnectionPool(host='localhost', port=80): Max retries exceeded with url: /api/users/ (Caused by NewConnectionError('<urllib3.connection.HTTPConnection object at 0x7fb31f9fe1d0>: Failed to establish a new connection: [Errno 111] Connection refused'))","time":{"start":1689189537967,"stop":1689189537969,"duration":2}}]},"tags":["test_negative_user_registration","order(1)","users_tests(scope='class')"]},"source":"efdeb0c66cb8c676.json","parameterValues":[]}