{"uid":"55fcb533a8ad50e","name":"test_negative_get_current_user","fullName":"tests.test_users.TestUsers#test_negative_get_current_user","historyId":"bdecc3c5cafe3f9ebebb59a04f24e6b8","time":{"start":1689187741461,"stop":1689187741462,"duration":1},"status":"broken","statusMessage":"requests.exceptions.ConnectionError: HTTPConnectionPool(host='localhost', port=80): Max retries exceeded with url: /api/users/me/ (Caused by NewConnectionError('<urllib3.connection.HTTPConnection object at 0x7f3f331e0bd0>: Failed to establish a new connection: [Errno 111] Connection refused'))","statusTrace":"E   ConnectionRefusedError: [Errno 111] Connection refused\n\nThe above exception was the direct cause of the following exception:\nE   urllib3.exceptions.NewConnectionError: <urllib3.connection.HTTPConnection object at 0x7f3f331e0bd0>: Failed to establish a new connection: [Errno 111] Connection refused\n\nThe above exception was the direct cause of the following exception:\nE   urllib3.exceptions.MaxRetryError: HTTPConnectionPool(host='localhost', port=80): Max retries exceeded with url: /api/users/me/ (Caused by NewConnectionError('<urllib3.connection.HTTPConnection object at 0x7f3f331e0bd0>: Failed to establish a new connection: [Errno 111] Connection refused'))\n\nDuring handling of the above exception, another exception occurred:\nE   requests.exceptions.ConnectionError: HTTPConnectionPool(host='localhost', port=80): Max retries exceeded with url: /api/users/me/ (Caused by NewConnectionError('<urllib3.connection.HTTPConnection object at 0x7f3f331e0bd0>: Failed to establish a new connection: [Errno 111] Connection refused'))","flaky":false,"newFailed":false,"newBroken":false,"newPassed":false,"retriesCount":0,"retriesStatusChange":false,"beforeStages":[],"afterStages":[],"labels":[{"name":"story","value":"Тест получения информации о текущем пользователе, без авторизации."},{"name":"feature","value":"Тесты работы с пользователем."},{"name":"tag","value":"test_negative_get_current_user_not_logged"},{"name":"tag","value":"users_tests(scope='class')"},{"name":"tag","value":"order(1)"},{"name":"parentSuite","value":"tests"},{"name":"suite","value":"test_users"},{"name":"subSuite","value":"TestUsers"},{"name":"host","value":"fv-az1255-236"},{"name":"thread","value":"2339-MainThread"},{"name":"framework","value":"pytest"},{"name":"language","value":"cpython3"},{"name":"package","value":"tests.test_users"},{"name":"resultFormat","value":"allure2"}],"parameters":[],"links":[],"hidden":false,"retry":false,"extra":{"severity":"normal","retries":[],"categories":[{"name":"Test defects","matchedStatuses":[],"flaky":false}],"history":{"statistic":{"failed":0,"broken":2,"skipped":0,"passed":0,"unknown":0,"total":2},"items":[{"uid":"fd70c6b6e6237d2","reportUrl":"https://IlyaYaP.github.io/testing_api_foodgram/19//#testresult/fd70c6b6e6237d2","status":"broken","statusDetails":"requests.exceptions.ConnectionError: HTTPConnectionPool(host='localhost', port=80): Max retries exceeded with url: /api/users/me/ (Caused by NewConnectionError('<urllib3.connection.HTTPConnection object at 0x7fb95725ef10>: Failed to establish a new connection: [Errno 111] Connection refused'))","time":{"start":1689185539598,"stop":1689185539599,"duration":1}}]},"tags":["order(1)","test_negative_get_current_user_not_logged","users_tests(scope='class')"]},"source":"55fcb533a8ad50e.json","parameterValues":[]}