{"uid":"855927d3a33629db","name":"test_negative_create_recipe_user_not_logged","fullName":"tests.test_recipes.TestRecipeCreation#test_negative_create_recipe_user_not_logged","historyId":"f27bc5b997e6f4038ef2c5a6bf35e262","time":{"start":1689187741523,"stop":1689187741525,"duration":2},"status":"broken","statusMessage":"requests.exceptions.ConnectionError: HTTPConnectionPool(host='localhost', port=80): Max retries exceeded with url: /api/recipes/ (Caused by NewConnectionError('<urllib3.connection.HTTPConnection object at 0x7f3f33200a90>: Failed to establish a new connection: [Errno 111] Connection refused'))","statusTrace":"E   ConnectionRefusedError: [Errno 111] Connection refused\n\nThe above exception was the direct cause of the following exception:\nE   urllib3.exceptions.NewConnectionError: <urllib3.connection.HTTPConnection object at 0x7f3f33200a90>: Failed to establish a new connection: [Errno 111] Connection refused\n\nThe above exception was the direct cause of the following exception:\nE   urllib3.exceptions.MaxRetryError: HTTPConnectionPool(host='localhost', port=80): Max retries exceeded with url: /api/recipes/ (Caused by NewConnectionError('<urllib3.connection.HTTPConnection object at 0x7f3f33200a90>: Failed to establish a new connection: [Errno 111] Connection refused'))\n\nDuring handling of the above exception, another exception occurred:\nE   requests.exceptions.ConnectionError: HTTPConnectionPool(host='localhost', port=80): Max retries exceeded with url: /api/recipes/ (Caused by NewConnectionError('<urllib3.connection.HTTPConnection object at 0x7f3f33200a90>: Failed to establish a new connection: [Errno 111] Connection refused'))","flaky":false,"newFailed":false,"newBroken":false,"newPassed":false,"retriesCount":0,"retriesStatusChange":false,"beforeStages":[],"afterStages":[],"labels":[{"name":"story","value":"Тест создания рецепта, без авторизации."},{"name":"feature","value":"Тесты создания рецептов."},{"name":"tag","value":"test_negative_create_recipe_user_not_logged"},{"name":"tag","value":"recipe_creation_tests(scope='class')"},{"name":"tag","value":"order(2)"},{"name":"parentSuite","value":"tests"},{"name":"suite","value":"test_recipes"},{"name":"subSuite","value":"TestRecipeCreation"},{"name":"host","value":"fv-az1255-236"},{"name":"thread","value":"2339-MainThread"},{"name":"framework","value":"pytest"},{"name":"language","value":"cpython3"},{"name":"package","value":"tests.test_recipes"},{"name":"resultFormat","value":"allure2"}],"parameters":[],"links":[],"hidden":false,"retry":false,"extra":{"severity":"normal","retries":[],"categories":[{"name":"Test defects","matchedStatuses":[],"flaky":false}],"history":{"statistic":{"failed":0,"broken":2,"skipped":0,"passed":0,"unknown":0,"total":2},"items":[{"uid":"1a2c42cf99de9ca8","reportUrl":"https://IlyaYaP.github.io/testing_api_foodgram/19//#testresult/1a2c42cf99de9ca8","status":"broken","statusDetails":"requests.exceptions.ConnectionError: HTTPConnectionPool(host='localhost', port=80): Max retries exceeded with url: /api/recipes/ (Caused by NewConnectionError('<urllib3.connection.HTTPConnection object at 0x7fb957286050>: Failed to establish a new connection: [Errno 111] Connection refused'))","time":{"start":1689185539672,"stop":1689185539673,"duration":1}}]},"tags":["order(2)","test_negative_create_recipe_user_not_logged","recipe_creation_tests(scope='class')"]},"source":"855927d3a33629db.json","parameterValues":[]}