{"uid":"c05ec1426f4f6a70","name":"test_get_recipe","fullName":"tests.test_recipes.TestRecipeCreation#test_get_recipe","historyId":"c10642315bdc1772ce7d3e4eca2b01fb","time":{"start":1689187741530,"stop":1689187741531,"duration":1},"status":"broken","statusMessage":"requests.exceptions.ConnectionError: HTTPConnectionPool(host='localhost', port=80): Max retries exceeded with url: /api/recipes/ (Caused by NewConnectionError('<urllib3.connection.HTTPConnection object at 0x7f3f331f62d0>: Failed to establish a new connection: [Errno 111] Connection refused'))","statusTrace":"E   ConnectionRefusedError: [Errno 111] Connection refused\n\nThe above exception was the direct cause of the following exception:\nE   urllib3.exceptions.NewConnectionError: <urllib3.connection.HTTPConnection object at 0x7f3f331f62d0>: Failed to establish a new connection: [Errno 111] Connection refused\n\nThe above exception was the direct cause of the following exception:\nE   urllib3.exceptions.MaxRetryError: HTTPConnectionPool(host='localhost', port=80): Max retries exceeded with url: /api/recipes/ (Caused by NewConnectionError('<urllib3.connection.HTTPConnection object at 0x7f3f331f62d0>: Failed to establish a new connection: [Errno 111] Connection refused'))\n\nDuring handling of the above exception, another exception occurred:\nE   requests.exceptions.ConnectionError: HTTPConnectionPool(host='localhost', port=80): Max retries exceeded with url: /api/recipes/ (Caused by NewConnectionError('<urllib3.connection.HTTPConnection object at 0x7f3f331f62d0>: Failed to establish a new connection: [Errno 111] Connection refused'))","flaky":false,"newFailed":false,"newBroken":false,"newPassed":false,"retriesCount":0,"retriesStatusChange":false,"beforeStages":[],"afterStages":[],"labels":[{"name":"story","value":"Тест получения рецепта."},{"name":"feature","value":"Тесты создания рецептов."},{"name":"tag","value":"test_get_recipe"},{"name":"tag","value":"recipe_creation_tests(scope='class')"},{"name":"tag","value":"order(2)"},{"name":"parentSuite","value":"tests"},{"name":"suite","value":"test_recipes"},{"name":"subSuite","value":"TestRecipeCreation"},{"name":"host","value":"fv-az1255-236"},{"name":"thread","value":"2339-MainThread"},{"name":"framework","value":"pytest"},{"name":"language","value":"cpython3"},{"name":"package","value":"tests.test_recipes"},{"name":"resultFormat","value":"allure2"}],"parameters":[],"links":[],"hidden":false,"retry":false,"extra":{"severity":"normal","retries":[],"categories":[{"name":"Test defects","matchedStatuses":[],"flaky":false}],"history":{"statistic":{"failed":0,"broken":2,"skipped":0,"passed":0,"unknown":0,"total":2},"items":[{"uid":"4832b0b4898adf61","reportUrl":"https://IlyaYaP.github.io/testing_api_foodgram/19//#testresult/4832b0b4898adf61","status":"broken","statusDetails":"requests.exceptions.ConnectionError: HTTPConnectionPool(host='localhost', port=80): Max retries exceeded with url: /api/recipes/ (Caused by NewConnectionError('<urllib3.connection.HTTPConnection object at 0x7fb95727aa90>: Failed to establish a new connection: [Errno 111] Connection refused'))","time":{"start":1689185539680,"stop":1689185539681,"duration":1}}]},"tags":["order(2)","test_get_recipe","recipe_creation_tests(scope='class')"]},"source":"c05ec1426f4f6a70.json","parameterValues":[]}