{"uid":"c907777ec1493f84","name":"test_negative_delete_token_user_not_logged","fullName":"tests.test_users.TestUsers#test_negative_delete_token_user_not_logged","historyId":"3d8c2310dcdf0fa09ef77963288beaae","time":{"start":1689187741499,"stop":1689187741500,"duration":1},"status":"broken","statusMessage":"requests.exceptions.ConnectionError: HTTPConnectionPool(host='localhost', port=80): Max retries exceeded with url: /api/auth/token/logout/ (Caused by NewConnectionError('<urllib3.connection.HTTPConnection object at 0x7f3f33201d90>: Failed to establish a new connection: [Errno 111] Connection refused'))","statusTrace":"E   ConnectionRefusedError: [Errno 111] Connection refused\n\nThe above exception was the direct cause of the following exception:\nE   urllib3.exceptions.NewConnectionError: <urllib3.connection.HTTPConnection object at 0x7f3f33201d90>: Failed to establish a new connection: [Errno 111] Connection refused\n\nThe above exception was the direct cause of the following exception:\nE   urllib3.exceptions.MaxRetryError: HTTPConnectionPool(host='localhost', port=80): Max retries exceeded with url: /api/auth/token/logout/ (Caused by NewConnectionError('<urllib3.connection.HTTPConnection object at 0x7f3f33201d90>: Failed to establish a new connection: [Errno 111] Connection refused'))\n\nDuring handling of the above exception, another exception occurred:\nE   requests.exceptions.ConnectionError: HTTPConnectionPool(host='localhost', port=80): Max retries exceeded with url: /api/auth/token/logout/ (Caused by NewConnectionError('<urllib3.connection.HTTPConnection object at 0x7f3f33201d90>: Failed to establish a new connection: [Errno 111] Connection refused'))","flaky":false,"newFailed":false,"newBroken":false,"newPassed":false,"retriesCount":0,"retriesStatusChange":false,"beforeStages":[],"afterStages":[],"labels":[{"name":"story","value":"Тест удаления токена, без авторизации."},{"name":"feature","value":"Тесты работы с пользователем."},{"name":"tag","value":"test_delete_token_user_not_logged"},{"name":"tag","value":"users_tests(scope='class')"},{"name":"tag","value":"order(1)"},{"name":"parentSuite","value":"tests"},{"name":"suite","value":"test_users"},{"name":"subSuite","value":"TestUsers"},{"name":"host","value":"fv-az1255-236"},{"name":"thread","value":"2339-MainThread"},{"name":"framework","value":"pytest"},{"name":"language","value":"cpython3"},{"name":"package","value":"tests.test_users"},{"name":"resultFormat","value":"allure2"}],"parameters":[],"links":[],"hidden":false,"retry":false,"extra":{"severity":"normal","retries":[],"categories":[{"name":"Test defects","matchedStatuses":[],"flaky":false}],"history":{"statistic":{"failed":0,"broken":2,"skipped":0,"passed":0,"unknown":0,"total":2},"items":[{"uid":"8b88c6e4d03bf478","reportUrl":"https://IlyaYaP.github.io/testing_api_foodgram/19//#testresult/8b88c6e4d03bf478","status":"broken","statusDetails":"requests.exceptions.ConnectionError: HTTPConnectionPool(host='localhost', port=80): Max retries exceeded with url: /api/auth/token/logout/ (Caused by NewConnectionError('<urllib3.connection.HTTPConnection object at 0x7fb9572850d0>: Failed to establish a new connection: [Errno 111] Connection refused'))","time":{"start":1689185539643,"stop":1689185539645,"duration":2}}]},"tags":["test_delete_token_user_not_logged","order(1)","users_tests(scope='class')"]},"source":"c907777ec1493f84.json","parameterValues":[]}