{"uid":"d514e832a506bb71","name":"test_negative_get_user_profile_not_logged","fullName":"tests.test_users.TestUsers#test_negative_get_user_profile_not_logged","historyId":"4d8270dc613966068cdf37650e0c3f1b","time":{"start":1689187741447,"stop":1689187741448,"duration":1},"status":"broken","statusMessage":"requests.exceptions.ConnectionError: HTTPConnectionPool(host='localhost', port=80): Max retries exceeded with url: /api/users/1/ (Caused by NewConnectionError('<urllib3.connection.HTTPConnection object at 0x7f3f3314fd50>: Failed to establish a new connection: [Errno 111] Connection refused'))","statusTrace":"E   ConnectionRefusedError: [Errno 111] Connection refused\n\nThe above exception was the direct cause of the following exception:\nE   urllib3.exceptions.NewConnectionError: <urllib3.connection.HTTPConnection object at 0x7f3f3314fd50>: Failed to establish a new connection: [Errno 111] Connection refused\n\nThe above exception was the direct cause of the following exception:\nE   urllib3.exceptions.MaxRetryError: HTTPConnectionPool(host='localhost', port=80): Max retries exceeded with url: /api/users/1/ (Caused by NewConnectionError('<urllib3.connection.HTTPConnection object at 0x7f3f3314fd50>: Failed to establish a new connection: [Errno 111] Connection refused'))\n\nDuring handling of the above exception, another exception occurred:\nE   requests.exceptions.ConnectionError: HTTPConnectionPool(host='localhost', port=80): Max retries exceeded with url: /api/users/1/ (Caused by NewConnectionError('<urllib3.connection.HTTPConnection object at 0x7f3f3314fd50>: Failed to establish a new connection: [Errno 111] Connection refused'))","flaky":false,"newFailed":false,"newBroken":false,"newPassed":false,"retriesCount":0,"retriesStatusChange":false,"beforeStages":[],"afterStages":[],"labels":[{"name":"story","value":"Тест получения информации о пользователе, без авторизации."},{"name":"feature","value":"Тесты работы с пользователем."},{"name":"tag","value":"test_negative_get_user_profile_not_logged"},{"name":"tag","value":"users_tests(scope='class')"},{"name":"tag","value":"order(1)"},{"name":"parentSuite","value":"tests"},{"name":"suite","value":"test_users"},{"name":"subSuite","value":"TestUsers"},{"name":"host","value":"fv-az1255-236"},{"name":"thread","value":"2339-MainThread"},{"name":"framework","value":"pytest"},{"name":"language","value":"cpython3"},{"name":"package","value":"tests.test_users"},{"name":"resultFormat","value":"allure2"}],"parameters":[],"links":[],"hidden":false,"retry":false,"extra":{"severity":"normal","retries":[],"categories":[{"name":"Test defects","matchedStatuses":[],"flaky":false}],"history":{"statistic":{"failed":0,"broken":2,"skipped":0,"passed":0,"unknown":0,"total":2},"items":[{"uid":"cc24086b12ff93aa","reportUrl":"https://IlyaYaP.github.io/testing_api_foodgram/19//#testresult/cc24086b12ff93aa","status":"broken","statusDetails":"requests.exceptions.ConnectionError: HTTPConnectionPool(host='localhost', port=80): Max retries exceeded with url: /api/users/1/ (Caused by NewConnectionError('<urllib3.connection.HTTPConnection object at 0x7fb957202dd0>: Failed to establish a new connection: [Errno 111] Connection refused'))","time":{"start":1689185539581,"stop":1689185539582,"duration":1}}]},"tags":["order(1)","test_negative_get_user_profile_not_logged","users_tests(scope='class')"]},"source":"d514e832a506bb71.json","parameterValues":[]}