WARNING  urllib3.connectionpool:connectionpool.py:871 Retrying (Retry(total=9, connect=2, read=None, redirect=None, status=None)) after connection broken by 'NewConnectionError('<urllib3.connection.HTTPConnection object at 0x7f299b5f9fd0>: Failed to establish a new connection: [Errno 111] Connection refused')': /api/users/
WARNING  urllib3.connectionpool:connectionpool.py:871 Retrying (Retry(total=8, connect=1, read=None, redirect=None, status=None)) after connection broken by 'NewConnectionError('<urllib3.connection.HTTPConnection object at 0x7f299b3f19d0>: Failed to establish a new connection: [Errno 111] Connection refused')': /api/users/
WARNING  urllib3.connectionpool:connectionpool.py:871 Retrying (Retry(total=7, connect=0, read=None, redirect=None, status=None)) after connection broken by 'NewConnectionError('<urllib3.connection.HTTPConnection object at 0x7f299b3f2390>: Failed to establish a new connection: [Errno 111] Connection refused')': /api/users/