{"uid":"57ff0f2061891012","name":"test_get_users_list","fullName":"tests.test_users.TestUsers#test_get_users_list","historyId":"ed973a1c6247e086e2ca7b67f8861f99","time":{"start":1689189537910,"stop":1689189537912,"duration":2},"status":"broken","statusMessage":"requests.exceptions.ConnectionError: HTTPConnectionPool(host='localhost', port=80): Max retries exceeded with url: /api/users/ (Caused by NewConnectionError('<urllib3.connection.HTTPConnection object at 0x7fb32027cd10>: Failed to establish a new connection: [Errno 111] Connection refused'))","statusTrace":"E   ConnectionRefusedError: [Errno 111] Connection refused\n\nThe above exception was the direct cause of the following exception:\nE   urllib3.exceptions.NewConnectionError: <urllib3.connection.HTTPConnection object at 0x7fb32027cd10>: Failed to establish a new connection: [Errno 111] Connection refused\n\nThe above exception was the direct cause of the following exception:\nE   urllib3.exceptions.MaxRetryError: HTTPConnectionPool(host='localhost', port=80): Max retries exceeded with url: /api/users/ (Caused by NewConnectionError('<urllib3.connection.HTTPConnection object at 0x7fb32027cd10>: Failed to establish a new connection: [Errno 111] Connection refused'))\n\nDuring handling of the above exception, another exception occurred:\nE   requests.exceptions.ConnectionError: HTTPConnectionPool(host='localhost', port=80): Max retries exceeded with url: /api/users/ (Caused by NewConnectionError('<urllib3.connection.HTTPConnection object at 0x7fb32027cd10>: Failed to establish a new connection: [Errno 111] Connection refused'))","flaky":false,"newFailed":false,"newBroken":false,"newPassed":false,"retriesCount":0,"retriesStatusChange":false,"beforeStages":[],"afterStages":[],"labels":[{"name":"feature","value":"Тесты работы с пользователем."},{"name":"story","value":"Тест получения списка пользователей."},{"name":"tag","value":"test_get_users_list"},{"name":"tag","value":"users_tests(scope='class')"},{"name":"tag","value":"order(1)"},{"name":"parentSuite","value":"tests"},{"name":"suite","value":"test_users"},{"name":"subSuite","value":"TestUsers"},{"name":"host","value":"fv-az309-816"},{"name":"thread","value":"2346-MainThread"},{"name":"framework","value":"pytest"},{"name":"language","value":"cpython3"},{"name":"package","value":"tests.test_users"},{"name":"resultFormat","value":"allure2"}],"parameters":[],"links":[],"hidden":false,"retry":false,"extra":{"severity":"normal","retries":[],"categories":[{"name":"Test defects","matchedStatuses":[],"flaky":false}],"tags":["order(1)","test_get_users_list","users_tests(scope='class')"]},"source":"57ff0f2061891012.json","parameterValues":[]}