{"uid":"8e70bf97e7209142","name":"test_negative_changing_password_validation_error","fullName":"tests.test_users.TestUsers#test_negative_changing_password_validation_error","historyId":"12b8b637aa4c2d424e0f293f6e1a6261","time":{"start":1689189538023,"stop":1689189538025,"duration":2},"status":"broken","statusMessage":"requests.exceptions.ConnectionError: HTTPConnectionPool(host='localhost', port=80): Max retries exceeded with url: /api/auth/token/login/ (Caused by NewConnectionError('<urllib3.connection.HTTPConnection object at 0x7fb31fa3f9d0>: Failed to establish a new connection: [Errno 111] Connection refused'))","statusTrace":"E   ConnectionRefusedError: [Errno 111] Connection refused\n\nThe above exception was the direct cause of the following exception:\nE   urllib3.exceptions.NewConnectionError: <urllib3.connection.HTTPConnection object at 0x7fb31fa3f9d0>: Failed to establish a new connection: [Errno 111] Connection refused\n\nThe above exception was the direct cause of the following exception:\nE   urllib3.exceptions.MaxRetryError: HTTPConnectionPool(host='localhost', port=80): Max retries exceeded with url: /api/auth/token/login/ (Caused by NewConnectionError('<urllib3.connection.HTTPConnection object at 0x7fb31fa3f9d0>: Failed to establish a new connection: [Errno 111] Connection refused'))\n\nDuring handling of the above exception, another exception occurred:\nE   requests.exceptions.ConnectionError: HTTPConnectionPool(host='localhost', port=80): Max retries exceeded with url: /api/auth/token/login/ (Caused by NewConnectionError('<urllib3.connection.HTTPConnection object at 0x7fb31fa3f9d0>: Failed to establish a new connection: [Errno 111] Connection refused'))","flaky":false,"newFailed":false,"newBroken":false,"newPassed":false,"retriesCount":0,"retriesStatusChange":false,"beforeStages":[],"testStage":{"status":"broken","statusMessage":"requests.exceptions.ConnectionError: HTTPConnectionPool(host='localhost', port=80): Max retries exceeded with url: /api/auth/token/login/ (Caused by NewConnectionError('<urllib3.connection.HTTPConnection object at 0x7fb31fa3f9d0>: Failed to establish a new connection: [Errno 111] Connection refused'))","statusTrace":"E   ConnectionRefusedError: [Errno 111] Connection refused\n\nThe above exception was the direct cause of the following exception:\nE   urllib3.exceptions.NewConnectionError: <urllib3.connection.HTTPConnection object at 0x7fb31fa3f9d0>: Failed to establish a new connection: [Errno 111] Connection refused\n\nThe above exception was the direct cause of the following exception:\nE   urllib3.exceptions.MaxRetryError: HTTPConnectionPool(host='localhost', port=80): Max retries exceeded with url: /api/auth/token/login/ (Caused by NewConnectionError('<urllib3.connection.HTTPConnection object at 0x7fb31fa3f9d0>: Failed to establish a new connection: [Errno 111] Connection refused'))\n\nDuring handling of the above exception, another exception occurred:\nE   requests.exceptions.ConnectionError: HTTPConnectionPool(host='localhost', port=80): Max retries exceeded with url: /api/auth/token/login/ (Caused by NewConnectionError('<urllib3.connection.HTTPConnection object at 0x7fb31fa3f9d0>: Failed to establish a new connection: [Errno 111] Connection refused'))","steps":[{"name":"Получаем токен.","time":{"start":1689189538023,"stop":1689189538024,"duration":1},"status":"broken","statusMessage":"requests.exceptions.ConnectionError: HTTPConnectionPool(host='localhost', port=80): Max retries exceeded with url: /api/auth/token/login/ (Caused by NewConnectionError('<urllib3.connection.HTTPConnection object at 0x7fb31fa3f9d0>: Failed to establish a new connection: [Errno 111] Connection refused'))\n","statusTrace":"  File \"/home/runner/work/testing_api_foodgram/testing_api_foodgram/src/base_validate.py\", line 34, in user_auth_token\n    r = requests.post(url=UsersEndPoints.USER_TOKEN, data=data)\n        ^^^^^^^^^^^^^^^^^^^^^^^^^^^^^^^^^^^^^^^^^^^^^^^^^^^^^^^\n  File \"/opt/hostedtoolcache/Python/3.11.4/x64/lib/python3.11/site-packages/requests/api.py\", line 115, in post\n    return request(\"post\", url, data=data, json=json, **kwargs)\n           ^^^^^^^^^^^^^^^^^^^^^^^^^^^^^^^^^^^^^^^^^^^^^^^^^^^^\n  File \"/opt/hostedtoolcache/Python/3.11.4/x64/lib/python3.11/site-packages/requests/api.py\", line 59, in request\n    return session.request(method=method, url=url, **kwargs)\n           ^^^^^^^^^^^^^^^^^^^^^^^^^^^^^^^^^^^^^^^^^^^^^^^^^\n  File \"/opt/hostedtoolcache/Python/3.11.4/x64/lib/python3.11/site-packages/requests/sessions.py\", line 589, in request\n    resp = self.send(prep, **send_kwargs)\n           ^^^^^^^^^^^^^^^^^^^^^^^^^^^^^^\n  File \"/opt/hostedtoolcache/Python/3.11.4/x64/lib/python3.11/site-packages/requests/sessions.py\", line 703, in send\n    r = adapter.send(request, **kwargs)\n        ^^^^^^^^^^^^^^^^^^^^^^^^^^^^^^^\n  File \"/opt/hostedtoolcache/Python/3.11.4/x64/lib/python3.11/site-packages/requests/adapters.py\", line 519, in send\n    raise ConnectionError(e, request=request)\n","steps":[],"attachments":[],"parameters":[],"stepsCount":0,"attachmentsCount":0,"shouldDisplayMessage":true,"hasContent":true}],"attachments":[],"parameters":[],"stepsCount":1,"attachmentsCount":0,"shouldDisplayMessage":true,"hasContent":true},"afterStages":[],"labels":[{"name":"story","value":"Тест изменения пароля, с некорректными данными."},{"name":"feature","value":"Тесты работы с пользователем."},{"name":"tag","value":"test_changing_password_validation_error"},{"name":"tag","value":"users_tests(scope='class')"},{"name":"tag","value":"order(1)"},{"name":"parentSuite","value":"tests"},{"name":"suite","value":"test_users"},{"name":"subSuite","value":"TestUsers"},{"name":"host","value":"fv-az309-816"},{"name":"thread","value":"2346-MainThread"},{"name":"framework","value":"pytest"},{"name":"language","value":"cpython3"},{"name":"package","value":"tests.test_users"},{"name":"resultFormat","value":"allure2"}],"parameters":[],"links":[],"hidden":false,"retry":false,"extra":{"severity":"normal","retries":[],"categories":[{"name":"Test defects","matchedStatuses":[],"flaky":false}],"tags":["test_changing_password_validation_error","order(1)","users_tests(scope='class')"]},"source":"8e70bf97e7209142.json","parameterValues":[]}